Traceback (most recent call last):
  File "d:\ProgramData\Anaconda3\envs\pth\lib\site-packages\jupyter_cache\executors\utils.py", line 58, in single_nb_execution
    executenb(
  File "d:\ProgramData\Anaconda3\envs\pth\lib\site-packages\nbclient\client.py", line 1314, in execute
    return NotebookClient(nb=nb, resources=resources, km=km, **kwargs).execute()
  File "d:\ProgramData\Anaconda3\envs\pth\lib\site-packages\jupyter_core\utils\__init__.py", line 173, in wrapped
    return loop.run_until_complete(inner)
  File "d:\ProgramData\Anaconda3\envs\pth\lib\asyncio\base_events.py", line 649, in run_until_complete
    return future.result()
  File "d:\ProgramData\Anaconda3\envs\pth\lib\site-packages\nbclient\client.py", line 709, in async_execute
    await self.async_execute_cell(
  File "d:\ProgramData\Anaconda3\envs\pth\lib\site-packages\nbclient\client.py", line 1062, in async_execute_cell
    await self._check_raise_for_error(cell, cell_index, exec_reply)
  File "d:\ProgramData\Anaconda3\envs\pth\lib\site-packages\nbclient\client.py", line 918, in _check_raise_for_error
    raise CellExecutionError.from_cell_and_msg(cell, exec_reply_content)
nbclient.exceptions.CellExecutionError: An error occurred while executing the following cell:
------------------
from live_plot import init_2dplot, add_point_2d
------------------


[1;31m---------------------------------------------------------------------------[0m
[1;31mModuleNotFoundError[0m                       Traceback (most recent call last)
Cell [1;32mIn[13], line 1[0m
[1;32m----> 1[0m [38;5;28;01mfrom[39;00m [38;5;21;01mlive_plot[39;00m [38;5;28;01mimport[39;00m init_2dplot, add_point_2d

[1;31mModuleNotFoundError[0m: No module named 'live_plot'

